Workbook

Sheet README
B2: IPL Match Analytics 2008-2019: Excel workbook (Data Analytics mini project)
B4: Data: match-level IPL results 2008-2019 (756 matches), from a public copy of the widely used Kaggle 'IPL' matches dataset on GitHub (srinathkr07/IPL-Data-Analysis). Confirm the source licence before publishing. It has no ball-by-ball data, so there are no batting or bowling totals, and it stops at the 2019 season.
B6: Cleaning done (see the CleaningLog sheet): mixed date formats fixed, duplicate team and venue spellings merged, missing cities filled.
B8: Sheets
B9: Matches: 756 matches. Columns P to Z are formulas (INDEX/MATCH lookups, CONCATENATE with &, IF flags, outlier check).
B10: Teams, Venues: lookup tables. Summary: COUNTIFS summaries and charts. Stats: central tendency, spread, IQR outliers, histogram.
B12: To add real PivotTables (as in your worksheet)
B13: Click a cell in Matches > Insert > PivotTable. Rows: Winner, Values: Count of match_id. Add Season as a column field, or Group the match_date by Years.

Sheet Teams
A1: team_id | B1: team_name | C1: home_city | D1: status
A2: T01 | B2: Chennai Super Kings | C2: Chennai | D2: Active
A3: T02 | B3: Deccan Chargers | C3: Hyderabad | D3: Defunct
A4: T03 | B4: Delhi Capitals | C4: Delhi | D4: Active
A5: T04 | B5: Gujarat Lions | C5: Rajkot | D5: Defunct
A6: T05 | B6: Kings XI Punjab | C6: Chandigarh | D6: Active
A7: T06 | B7: Kochi Tuskers Kerala | C7: Kochi | D7: Defunct
A8: T07 | B8: Kolkata Knight Riders | C8: Kolkata | D8: Active
A9: T08 | B9: Mumbai Indians | C9: Mumbai | D9: Active
A10: T09 | B10: Pune Warriors | C10: Pune | D10: Defunct
A11: T10 | B11: Rajasthan Royals | C11: Jaipur | D11: Active
A12: T11 | B12: Rising Pune Supergiant | C12: Pune | D12: Defunct
... A14: T13 | B14: Sunrisers Hyderabad | C14: Hyderabad | D14: Active

Sheet Venues
A1: venue_id | B1: venue_name | C1: city
A2: V01 | B2: Barabati Stadium | C2: Cuttack
A3: V02 | B3: Brabourne Stadium | C3: Mumbai
A4: V03 | B4: Buffalo Park | C4: East London
A5: V04 | B5: De Beers Diamond Oval | C5: Kimberley
A6: V05 | B6: Dr DY Patil Sports Academy | C6: Mumbai
A7: V06 | B7: Dr. Y.S. Rajasekhara Reddy ACA-VDCA Cricket Stadium | C7: Visakhapatnam
A8: V07 | B8: Dubai International Cricket Stadium | C8: Dubai
A9: V08 | B9: Eden Gardens | C9: Kolkata
A10: V09 | B10: Feroz Shah Kotla | C10: Delhi
A11: V10 | B11: Green Park | C11: Kanpur
A12: V11 | B12: Himachal Pradesh Cricket Association Stadium | C12: Dharamsala
... A34: V33 | B34: Wankhede Stadium | C34: Mumbai

Sheet CleaningLog
A1: cleaning_step | B1: rows_affected
A2: Dates in dd/mm/yy format converted to ISO | B2: 120
A3: Team-name cells standardised (Delhi Daredevils to Delhi Capitals, Supergiants to Supergiant) | B3: 334
A4: Venue names standardised (duplicate spellings merged) | B4: 225
A5: Missing city filled from venue | B5: 7
A6: Matches with no winner (no result) | B6: 4

Sheet Matches
A1: match_id | B1: season | C1: match_date | D1: stage | E1: team1_id | F1: team2_id | G1: toss_winner_id | H1: toss_decision | I1: result | J1: dl_applied | K1: winner_id | L1: win_by_runs | M1: win_by_wickets | N1: player_of_match | O1: venue_id | P1: Team1 | Q1: Team2 | R1: TossWinner | S1: Winner | T1: Venue | U1: City | V1: Margin | W1: TossWinnerWon | X1: RunMargin | Y1: Outlier? | Z1: Match
A2: 60 | B2: 2008 | C2: 39556 | D2: League/Playoff | E2: T07 | F2: T12 | G2: T12 | H2: field | I2: normal | J2: 0 | K2: T07 | L2: 140 | M2: 0 | N2: BB McCullum | O2: V15 | P2: =INDEX(Teams!$B:$B,MATCH(E2,Teams!$A:$A,0)) -> Kolkata Knight Riders | Q2: =INDEX(Teams!$B:$B,MATCH(F2,Teams!$A:$A,0)) -> Royal Challengers Bangalore | R2: =INDEX(Teams!$B:$B,MATCH(G2,Teams!$A:$A,0)) -> Royal Challengers Bangalore | S2: =IF(K2="","No result",INDEX(Teams!$B:$B,MATCH(K2,Teams!$A:$A,0))) -> Kolkata Knight Riders | T2: =INDEX(Venues!$B:$B,MATCH(O2,Venues!$A:$A,0)) -> M Chinnaswamy Stadium | U2: =INDEX(Venues!$C:$C,MATCH(O2,Venues!$A:$A,0)) -> Bangalore | V2: =IF(L2>0,L2&" runs",IF(M2>0,M2&" wickets","-")) -> 140 runs | W2: =IF(G2=K2,1,0) -> 0 | X2: =IF(L2>0,L2,"") -> 140 | Y2: =IF(X2="","",IF(X2>Stats!$B$15,"Outlier","")) -> Outlier | Z2: =P2&" vs "&Q2 -> Kolkata Knight Riders vs Royal Challengers Bangalore
A3: 61 | B3: 2008 | C3: 39557 | D3: League/Playoff | E3: T01 | F3: T05 | G3: T01 | H3: bat | I3: normal | J3: 0 | K3: T01 | L3: 33 | M3: 0 | N3: MEK Hussey | O3: V22 | P3: =INDEX(Teams!$B:$B,MATCH(E3,Teams!$A:$A,0)) -> Chennai Super Kings | Q3: =INDEX(Teams!$B:$B,MATCH(F3,Teams!$A:$A,0)) -> Kings XI Punjab | R3: =INDEX(Teams!$B:$B,MATCH(G3,Teams!$A:$A,0)) -> Chennai Super Kings | S3: =IF(K3="","No result",INDEX(Teams!$B:$B,MATCH(K3,Teams!$A:$A,0))) -> Chennai Super Kings | T3: =INDEX(Venues!$B:$B,MATCH(O3,Venues!$A:$A,0)) -> Punjab Cricket Association IS Bindra Stadium | U3: =INDEX(Venues!$C:$C,MATCH(O3,Venues!$A:$A,0)) -> Chandigarh | V3: =IF(L3>0,L3&" runs",IF(M3>0,M3&" wickets","-")) -> 33 runs | W3: =IF(G3=K3,1,0) -> 1 | X3: =IF(L3>0,L3,"") -> 33 | Y3: =IF(X3="","",IF(X3>Stats!$B$15,"Outlier","")) | Z3: =P3&" vs "&Q3 -> Chennai Super Kings vs Kings XI Punjab
A4: 62 | B4: 2008 | C4: 39557 | D4: League/Playoff | E4: T10 | F4: T03 | G4: T10 | H4: bat | I4: normal | J4: 0 | K4: T03 | L4: 0 | M4: 9 | N4: MF Maharoof | O4: V09 | P4: =INDEX(Teams!$B:$B,MATCH(E4,Teams!$A:$A,0)) -> Rajasthan Royals | Q4: =INDEX(Teams!$B:$B,MATCH(F4,Teams!$A:$A,0)) -> Delhi Capitals | R4: =INDEX(Teams!$B:$B,MATCH(G4,Teams!$A:$A,0)) -> Rajasthan Royals | S4: =IF(K4="","No result",INDEX(Teams!$B:$B,MATCH(K4,Teams!$A:$A,0))) -> Delhi Capitals | T4: =INDEX(Venues!$B:$B,MATCH(O4,Venues!$A:$A,0)) -> Feroz Shah Kotla | U4: =INDEX(Venues!$C:$C,MATCH(O4,Venues!$A:$A,0)) -> Delhi | V4: =IF(L4>0,L4&" runs",IF(M4>0,M4&" wickets","-")) -> 9 wickets | W4: =IF(G4=K4,1,0) -> 0 | X4: =IF(L4>0,L4,"") | Y4: =IF(X4="","",IF(X4>Stats!$B$15,"Outlier","")) | Z4: =P4&" vs "&Q4 -> Rajasthan Royals vs Delhi Capitals
A5: 63 | B5: 2008 | C5: 39558 | D5: League/Playoff | E5: T08 | F5: T12 | G5: T08 | H5: bat | I5: normal | J5: 0 | K5: T12 | L5: 0 | M5: 5 | N5: MV Boucher | O5: V33 | P5: =INDEX(Teams!$B:$B,MATCH(E5,Teams!$A:$A,0)) -> Mumbai Indians | Q5: =INDEX(Teams!$B:$B,MATCH(F5,Teams!$A:$A,0)) -> Royal Challengers Bangalore | R5: =INDEX(Teams!$B:$B,MATCH(G5,Teams!$A:$A,0)) -> Mumbai Indians | S5: =IF(K5="","No result",INDEX(Teams!$B:$B,MATCH(K5,Teams!$A:$A,0))) -> Royal Challengers Bangalore | T5: =INDEX(Venues!$B:$B,MATCH(O5,Venues!$A:$A,0)) -> Wankhede Stadium | U5: =INDEX(Venues!$C:$C,MATCH(O5,Venues!$A:$A,0)) -> Mumbai | V5: =IF(L5>0,L5&" runs",IF(M5>0,M5&" wickets","-")) -> 5 wickets | W5: =IF(G5=K5,1,0) -> 0 | X5: =IF(L5>0,L5,"") | Y5: =IF(X5="","",IF(X5>Stats!$B$15,"Outlier","")) | Z5: =P5&" vs "&Q5 -> Mumbai Indians vs Royal Challengers Bangalore
A6: 64 | B6: 2008 | C6: 39558 | D6: League/Playoff | E6: T02 | F6: T07 | G6: T02 | H6: bat | I6: normal | J6: 0 | K6: T07 | L6: 0 | M6: 5 | N6: DJ Hussey | O6: V08 | P6: =INDEX(Teams!$B:$B,MATCH(E6,Teams!$A:$A,0)) -> Deccan Chargers | Q6: =INDEX(Teams!$B:$B,MATCH(F6,Teams!$A:$A,0)) -> Kolkata Knight Riders | R6: =INDEX(Teams!$B:$B,MATCH(G6,Teams!$A:$A,0)) -> Deccan Chargers | S6: =IF(K6="","No result",INDEX(Teams!$B:$B,MATCH(K6,Teams!$A:$A,0))) -> Kolkata Knight Riders | T6: =INDEX(Venues!$B:$B,MATCH(O6,Venues!$A:$A,0)) -> Eden Gardens | U6: =INDEX(Venues!$C:$C,MATCH(O6,Venues!$A:$A,0)) -> Kolkata | V6: =IF(L6>0,L6&" runs",IF(M6>0,M6&" wickets","-")) -> 5 wickets | W6: =IF(G6=K6,1,0) -> 0 | X6: =IF(L6>0,L6,"") | Y6: =IF(X6="","",IF(X6>Stats!$B$15,"Outlier","")) | Z6: =P6&" vs "&Q6 -> Deccan Chargers vs Kolkata Knight Riders
A7: 65 | B7: 2008 | C7: 39559 | D7: League/Playoff | E7: T05 | F7: T10 | G7: T05 | H7: bat | I7: normal | J7: 0 | K7: T10 | L7: 0 | M7: 6 | N7: SR Watson | O7: V26 | P7: =INDEX(Teams!$B:$B,MATCH(E7,Teams!$A:$A,0)) -> Kings XI Punjab | Q7: =INDEX(Teams!$B:$B,MATCH(F7,Teams!$A:$A,0)) -> Rajasthan Royals | R7: =INDEX(Teams!$B:$B,MATCH(G7,Teams!$A:$A,0)) -> Kings XI Punjab | S7: =IF(K7="","No result",INDEX(Teams!$B:$B,MATCH(K7,Teams!$A:$A,0))) -> Rajasthan Royals | T7: =INDEX(Venues!$B:$B,MATCH(O7,Venues!$A:$A,0)) -> Sawai Mansingh Stadium | U7: =INDEX(Venues!$C:$C,MATCH(O7,Venues!$A:$A,0)) -> Jaipur | V7: =IF(L7>0,L7&" runs",IF(M7>0,M7&" wickets","-")) -> 6 wickets | W7: =IF(G7=K7,1,0) -> 0 | X7: =IF(L7>0,L7,"") | Y7: =IF(X7="","",IF(X7>Stats!$B$15,"Outlier","")) | Z7: =P7&" vs "&Q7 -> Kings XI Punjab vs Rajasthan Royals
A8: 66 | B8: 2008 | C8: 39560 | D8: League/Playoff | E8: T02 | F8: T03 | G8: T02 | H8: bat | I8: normal | J8: 0 | K8: T03 | L8: 0 | M8: 9 | N8: V Sehwag | O8: V23 | P8: =INDEX(Teams!$B:$B,MATCH(E8,Teams!$A:$A,0)) -> Deccan Chargers | Q8: =INDEX(Teams!$B:$B,MATCH(F8,Teams!$A:$A,0)) -> Delhi Capitals | R8: =INDEX(Teams!$B:$B,MATCH(G8,Teams!$A:$A,0)) -> Deccan Chargers | S8: =IF(K8="","No result",INDEX(Teams!$B:$B,MATCH(K8,Teams!$A:$A,0))) -> Delhi Capitals | T8: =INDEX(Venues!$B:$B,MATCH(O8,Venues!$A:$A,0)) -> Rajiv Gandhi International Stadium | U8: =INDEX(Venues!$C:$C,MATCH(O8,Venues!$A:$A,0)) -> Hyderabad | V8: =IF(L8>0,L8&" runs",IF(M8>0,M8&" wickets","-")) -> 9 wickets | W8: =IF(G8=K8,1,0) -> 0 | X8: =IF(L8>0,L8,"") | Y8: =IF(X8="","",IF(X8>Stats!$B$15,"Outlier","")) | Z8: =P8&" vs "&Q8 -> Deccan Chargers vs Delhi Capitals
A9: 67 | B9: 2008 | C9: 39561 | D9: League/Playoff | E9: T01 | F9: T08 | G9: T08 | H9: field | I9: normal | J9: 0 | K9: T01 | L9: 6 | M9: 0 | N9: ML Hayden | O9: V16 | P9: =INDEX(Teams!$B:$B,MATCH(E9,Teams!$A:$A,0)) -> Chennai Super Kings | Q9: =INDEX(Teams!$B:$B,MATCH(F9,Teams!$A:$A,0)) -> Mumbai Indians | R9: =INDEX(Teams!$B:$B,MATCH(G9,Teams!$A:$A,0)) -> Mumbai Indians | S9: =IF(K9="","No result",INDEX(Teams!$B:$B,MATCH(K9,Teams!$A:$A,0))) -> Chennai Super Kings | T9: =INDEX(Venues!$B:$B,MATCH(O9,Venues!$A:$A,0)) -> MA Chidambaram Stadium | U9: =INDEX(Venues!$C:$C,MATCH(O9,Venues!$A:$A,0)) -> Chennai | V9: =IF(L9>0,L9&" runs",IF(M9>0,M9&" wickets","-")) -> 6 runs | W9: =IF(G9=K9,1,0) -> 0 | X9: =IF(L9>0,L9,"") -> 6 | Y9: =IF(X9="","",IF(X9>Stats!$B$15,"Outlier","")) | Z9: =P9&" vs "&Q9 -> Chennai Super Kings vs Mumbai Indians
A10: 68 | B10: 2008 | C10: 39562 | D10: League/Playoff | E10: T02 | F10: T10 | G10: T10 | H10: field | I10: normal | J10: 0 | K10: T10 | L10: 0 | M10: 3 | N10: YK Pathan | O10: V23 | P10: =INDEX(Teams!$B:$B,MATCH(E10,Teams!$A:$A,0)) -> Deccan Chargers | Q10: =INDEX(Teams!$B:$B,MATCH(F10,Teams!$A:$A,0)) -> Rajasthan Royals | R10: =INDEX(Teams!$B:$B,MATCH(G10,Teams!$A:$A,0)) -> Rajasthan Royals | S10: =IF(K10="","No result",INDEX(Teams!$B:$B,MATCH(K10,Teams!$A:$A,0))) -> Rajasthan Royals | T10: =INDEX(Venues!$B:$B,MATCH(O10,Venues!$A:$A,0)) -> Rajiv Gandhi International Stadium | U10: =INDEX(Venues!$C:$C,MATCH(O10,Venues!$A:$A,0)) -> Hyderabad | V10: =IF(L10>0,L10&" runs",IF(M10>0,M10&" wickets","-")) -> 3 wickets | W10: =IF(G10=K10,1,0) -> 1 | X10: =IF(L10>0,L10,"") | Y10: =IF(X10="","",IF(X10>Stats!$B$15,"Outlier","")) | Z10: =P10&" vs "&Q10 -> Deccan Chargers vs Rajasthan Royals
A11: 69 | B11: 2008 | C11: 39563 | D11: League/Playoff | E11: T05 | F11: T08 | G11: T08 | H11: field | I11: normal | J11: 0 | K11: T05 | L11: 66 | M11: 0 | N11: KC Sangakkara | O11: V22 | P11: =INDEX(Teams!$B:$B,MATCH(E11,Teams!$A:$A,0)) -> Kings XI Punjab | Q11: =INDEX(Teams!$B:$B,MATCH(F11,Teams!$A:$A,0)) -> Mumbai Indians | R11: =INDEX(Teams!$B:$B,MATCH(G11,Teams!$A:$A,0)) -> Mumbai Indians | S11: =IF(K11="","No result",INDEX(Teams!$B:$B,MATCH(K11,Teams!$A:$A,0))) -> Kings XI Punjab | T11: =INDEX(Venues!$B:$B,MATCH(O11,Venues!$A:$A,0)) -> Punjab Cricket Association IS Bindra Stadium | U11: =INDEX(Venues!$C:$C,MATCH(O11,Venues!$A:$A,0)) -> Chandigarh | V11: =IF(L11>0,L11&" runs",IF(M11>0,M11&" wickets","-")) -> 66 runs | W11: =IF(G11=K11,1,0) -> 0 | X11: =IF(L11>0,L11,"") -> 66 | Y11: =IF(X11="","",IF(X11>Stats!$B$15,"Outlier","")) | Z11: =P11&" vs "&Q11 -> Kings XI Punjab vs Mumbai Indians
A12: 70 | B12: 2008 | C12: 39564 | D12: League/Playoff | E12: T12 | F12: T10 | G12: T10 | H12: field | I12: normal | J12: 0 | K12: T10 | L12: 0 | M12: 7 | N12: SR Watson | O12: V15 | P12: =INDEX(Teams!$B:$B,MATCH(E12,Teams!$A:$A,0)) -> Royal Challengers Bangalore | Q12: =INDEX(Teams!$B:$B,MATCH(F12,Teams!$A:$A,0)) -> Rajasthan Royals | R12: =INDEX(Teams!$B:$B,MATCH(G12,Teams!$A:$A,0)) -> Rajasthan Royals | S12: =IF(K12="","No result",INDEX(Teams!$B:$B,MATCH(K12,Teams!$A:$A,0))) -> Rajasthan Royals | T12: =INDEX(Venues!$B:$B,MATCH(O12,Venues!$A:$A,0)) -> M Chinnaswamy Stadium | U12: =INDEX(Venues!$C:$C,MATCH(O12,Venues!$A:$A,0)) -> Bangalore | V12: =IF(L12>0,L12&" runs",IF(M12>0,M12&" wickets","-")) -> 7 wickets | W12: =IF(G12=K12,1,0) -> 1 | X12: =IF(L12>0,L12,"") | Y12: =IF(X12="","",IF(X12>Stats!$B$15,"Outlier","")) | Z12: =P12&" vs "&Q12 -> Royal Challengers Bangalore vs Rajasthan Royals
A13: 71 | B13: 2008 | C13: 39564 | D13: League/Playoff | E13: T07 | F13: T01 | G13: T07 | H13: bat | I13: normal | J13: 0 | K13: T01 | L13: 0 | M13: 9 | N13: JDP Oram | O13: V16 | P13: =INDEX(Teams!$B:$B,MATCH(E13,Teams!$A:$A,0)) -> Kolkata Knight Riders | Q13: =INDEX(Teams!$B:$B,MATCH(F13,Teams!$A:$A,0)) -> Chennai Super Kings | R13: =INDEX(Teams!$B:$B,MATCH(G13,Teams!$A:$A,0)) -> Kolkata Knight Riders | S13: =IF(K13="","No result",INDEX(Teams!$B:$B,MATCH(K13,Teams!$A:$A,0))) -> Chennai Super Kings | T13: =INDEX(Venues!$B:$B,MATCH(O13,Venues!$A:$A,0)) -> MA Chidambaram Stadium | U13: =INDEX(Venues!$C:$C,MATCH(O13,Venues!$A:$A,0)) -> Chennai | V13: =IF(L13>0,L13&" runs",IF(M13>0,M13&" wickets","-")) -> 9 wickets | W13: =IF(G13=K13,1,0) -> 0 | X13: =IF(L13>0,L13,"") | Y13: =IF(X13="","",IF(X13>Stats!$B$15,"Outlier","")) | Z13: =P13&" vs "&Q13 -> Kolkata Knight Riders vs Chennai Super Kings
... A242: 300 | B242: 2011 | C242: 40684 | D242: League/Playoff | E242: T02 | F242: T05 | G242: T05 | H242: field | I242: normal | J242: 0 | K242: T02 | L242: 82 | M242: 0 | N242: S Dhawan | O242: V11 | P242: =INDEX(Teams!$B:$B,MATCH(E242,Teams!$A:$A,0)) -> Deccan Chargers | Q242: =INDEX(Teams!$B:$B,MATCH(F242,Teams!$A:$A,0)) -> Kings XI Punjab | R242: =INDEX(Teams!$B:$B,MATCH(G242,Teams!$A:$A,0)) -> Kings XI Punjab | S242: =IF(K242="","No result",INDEX(Teams!$B:$B,MATCH(K242,Teams!$A:$A,0))) -> Deccan Chargers | T242: =INDEX(Venues!$B:$B,MATCH(O242,Venues!$A:$A,0)) -> Himachal Pradesh Cricket Association Stadium | U242: =INDEX(Venues!$C:$C,MATCH(O242,Venues!$A:$A,0)) -> Dharamsala | V242: =IF(L242>0,L242&" runs",IF(M242>0,M242&" wickets","-")) -> 82 runs | W242: =IF(G242=K242,1,0) -> 0 | X242: =IF(L242>0,L242,"") -> 82 | Y242: =IF(X242="","",IF(X242>Stats!$B$15,"Outlier","")) -> Outlier | Z242: =P242&" vs "&Q242 -> Deccan Chargers vs Kings XI Punjab
A243: 301 | B243: 2011 | C243: 40684 | D243: League/Playoff | E243: T03 | F243: T09 | G243: T03 | H243: bat | I243: no result | J243: 0 | L243: 0 | M243: 0 | N243: Not awarded | O243: V09 | P243: =INDEX(Teams!$B:$B,MATCH(E243,Teams!$A:$A,0)) -> Delhi Capitals | Q243: =INDEX(Teams!$B:$B,MATCH(F243,Teams!$A:$A,0)) -> Pune Warriors | R243: =INDEX(Teams!$B:$B,MATCH(G243,Teams!$A:$A,0)) -> Delhi Capitals | S243: =IF(K243="","No result",INDEX(Teams!$B:$B,MATCH(K243,Teams!$A:$A,0))) -> No result | T243: =INDEX(Venues!$B:$B,MATCH(O243,Venues!$A:$A,0)) -> Feroz Shah Kotla | U243: =INDEX(Venues!$C:$C,MATCH(O243,Venues!$A:$A,0)) -> Delhi | V243: =IF(L243>0,L243&" runs",IF(M243>0,M243&" wickets","-")) -> - | W243: =IF(G243=K243,1,0) -> 0 | X243: =IF(L243>0,L243,"") | Y243: =IF(X243="","",IF(X243>Stats!$B$15,"Outlier","")) | Z243: =P243&" vs "&Q243 -> Delhi Capitals vs Pune Warriors
A244: 302 | B244: 2011 | C244: 40685 | D244: League/Playoff | E244: T01 | F244: T12 | G244: T12 | H244: field | I244: normal | J244: 0 | K244: T12 | L244: 0 | M244: 8 | N244: CH Gayle | O244: V15 | P244: =INDEX(Teams!$B:$B,MATCH(E244,Teams!$A:$A,0)) -> Chennai Super Kings | Q244: =INDEX(Teams!$B:$B,MATCH(F244,Teams!$A:$A,0)) -> Royal Challengers Bangalore | R244: =INDEX(Teams!$B:$B,MATCH(G244,Teams!$A:$A,0)) -> Royal Challengers Bangalore | S244: =IF(K244="","No result",INDEX(Teams!$B:$B,MATCH(K244,Teams!$A:$A,0))) -> Royal Challengers Bangalore | T244: =INDEX(Venues!$B:$B,MATCH(O244,Venues!$A:$A,0)) -> M Chinnaswamy Stadium | U244: =INDEX(Venues!$C:$C,MATCH(O244,Venues!$A:$A,0)) -> Bangalore | V244: =IF(L244>0,L244&" runs",IF(M244>0,M244&" wickets","-")) -> 8 wickets | W244: =IF(G244=K244,1,0) -> 1 | X244: =IF(L244>0,L244,"") | Y244: =IF(X244="","",IF(X244>Stats!$B$15,"Outlier","")) | Z244: =P244&" vs "&Q244 -> Chennai Super Kings vs Royal Challengers Bangalore
A245: 303 | B245: 2011 | C245: 40685 | D245: League/Playoff | E245: T07 | F245: T08 | G245: T08 | H245: field | I245: normal | J245: 0 | K245: T08 | L245: 0 | M245: 5 | N245: JEC Franklin | O245: V08 | P245: =INDEX(Teams!$B:$B,MATCH(E245,Teams!$A:$A,0)) -> Kolkata Knight Riders | Q245: =INDEX(Teams!$B:$B,MATCH(F245,Teams!$A:$A,0)) -> Mumbai Indians | R245: =INDEX(Teams!$B:$B,MATCH(G245,Teams!$A:$A,0)) -> Mumbai Indians | S245: =IF(K245="","No result",INDEX(Teams!$B:$B,MATCH(K245,Teams!$A:$A,0))) -> Mumbai Indians | T245: =INDEX(Venues!$B:$B,MATCH(O245,Venues!$A:$A,0)) -> Eden Gardens | U245: =INDEX(Venues!$C:$C,MATCH(O245,Venues!$A:$A,0)) -> Kolkata | V245: =IF(L245>0,L245&" runs",IF(M245>0,M245&" wickets","-")) -> 5 wickets | W245: =IF(G245=K245,1,0) -> 1 | X245: =IF(L245>0,L245,"") | Y245: =IF(X245="","",IF(X245>Stats!$B$15,"Outlier","")) | Z245: =P245&" vs "&Q245 -> Kolkata Knight Riders vs Mumbai Indians
A246: 304 | B246: 2011 | C246: 40687 | D246: League/Playoff | E246: T12 | F246: T01 | G246: T01 | H246: field | I246: normal | J246: 0 | K246: T01 | L246: 0 | M246: 6 | N246: SK Raina | O246: V33 | P246: =INDEX(Teams!$B:$B,MATCH(E246,Teams!$A:$A,0)) -> Royal Challengers Bangalore | Q246: =INDEX(Teams!$B:$B,MATCH(F246,Teams!$A:$A,0)) -> Chennai Super Kings | R246: =INDEX(Teams!$B:$B,MATCH(G246,Teams!$A:$A,0)) -> Chennai Super Kings | S246: =IF(K246="","No result",INDEX(Teams!$B:$B,MATCH(K246,Teams!$A:$A,0))) -> Chennai Super Kings | T246: =INDEX(Venues!$B:$B,MATCH(O246,Venues!$A:$A,0)) -> Wankhede Stadium | U246: =INDEX(Venues!$C:$C,MATCH(O246,Venues!$A:$A,0)) -> Mumbai | V246: =IF(L246>0,L246&" runs",IF(M246>0,M246&" wickets","-")) -> 6 wickets | W246: =IF(G246=K246,1,0) -> 1 | X246: =IF(L246>0,L246,"") | Y246: =IF(X246="","",IF(X246>Stats!$B$15,"Outlier","")) | Z246: =P246&" vs "&Q246 -> Royal Challengers Bangalore vs Chennai Super Kings
A247: 305 | B247: 2011 | C247: 40688 | D247: League/Playoff | E247: T07 | F247: T08 | G247: T08 | H247: field | I247: normal | J247: 0 | K247: T08 | L247: 0 | M247: 4 | N247: MM Patel | O247: V33 | P247: =INDEX(Teams!$B:$B,MATCH(E247,Teams!$A:$A,0)) -> Kolkata Knight Riders | Q247: =INDEX(Teams!$B:$B,MATCH(F247,Teams!$A:$A,0)) -> Mumbai Indians | R247: =INDEX(Teams!$B:$B,MATCH(G247,Teams!$A:$A,0)) -> Mumbai Indians | S247: =IF(K247="","No result",INDEX(Teams!$B:$B,MATCH(K247,Teams!$A:$A,0))) -> Mumbai Indians | T247: =INDEX(Venues!$B:$B,MATCH(O247,Venues!$A:$A,0)) -> Wankhede Stadium | U247: =INDEX(Venues!$C:$C,MATCH(O247,Venues!$A:$A,0)) -> Mumbai | V247: =IF(L247>0,L247&" runs",IF(M247>0,M247&" wickets","-")) -> 4 wickets | W247: =IF(G247=K247,1,0) -> 1 | X247: =IF(L247>0,L247,"") | Y247: =IF(X247="","",IF(X247>Stats!$B$15,"Outlier","")) | Z247: =P247&" vs "&Q247 -> Kolkata Knight Riders vs Mumbai Indians
A248: 306 | B248: 2011 | C248: 40690 | D248: League/Playoff | E248: T12 | F248: T08 | G248: T08 | H248: field | I248: normal | J248: 0 | K248: T12 | L248: 43 | M248: 0 | N248: CH Gayle | O248: V16 | P248: =INDEX(Teams!$B:$B,MATCH(E248,Teams!$A:$A,0)) -> Royal Challengers Bangalore | Q248: =INDEX(Teams!$B:$B,MATCH(F248,Teams!$A:$A,0)) -> Mumbai Indians | R248: =INDEX(Teams!$B:$B,MATCH(G248,Teams!$A:$A,0)) -> Mumbai Indians | S248: =IF(K248="","No result",INDEX(Teams!$B:$B,MATCH(K248,Teams!$A:$A,0))) -> Royal Challengers Bangalore | T248: =INDEX(Venues!$B:$B,MATCH(O248,Venues!$A:$A,0)) -> MA Chidambaram Stadium | U248: =INDEX(Venues!$C:$C,MATCH(O248,Venues!$A:$A,0)) -> Chennai | V248: =IF(L248>0,L248&" runs",IF(M248>0,M248&" wickets","-")) -> 43 runs | W248: =IF(G248=K248,1,0) -> 0 | X248: =IF(L248>0,L248,"") -> 43 | Y248: =IF(X248="","",IF(X248>Stats!$B$15,"Outlier","")) | Z248: =P248&" vs "&Q248 -> Royal Challengers Bangalore vs Mumbai Indians
A249: 307 | B249: 2011 | C249: 40691 | D249: Final | E249: T01 | F249: T12 | G249: T01 | H249: bat | I249: normal | J249: 0 | K249: T01 | L249: 58 | M249: 0 | N249: M Vijay | O249: V16 | P249: =INDEX(Teams!$B:$B,MATCH(E249,Teams!$A:$A,0)) -> Chennai Super Kings | Q249: =INDEX(Teams!$B:$B,MATCH(F249,Teams!$A:$A,0)) -> Royal Challengers Bangalore | R249: =INDEX(Teams!$B:$B,MATCH(G249,Teams!$A:$A,0)) -> Chennai Super Kings | S249: =IF(K249="","No result",INDEX(Teams!$B:$B,MATCH(K249,Teams!$A:$A,0))) -> Chennai Super Kings | T249: =INDEX(Venues!$B:$B,MATCH(O249,Venues!$A:$A,0)) -> MA Chidambaram Stadium | U249: =INDEX(Venues!$C:$C,MATCH(O249,Venues!$A:$A,0)) -> Chennai | V249: =IF(L249>0,L249&" runs",IF(M249>0,M249&" wickets","-")) -> 58 runs | W249: =IF(G249=K249,1,0) -> 1 | X249: =IF(L249>0,L249,"") -> 58 | Y249: =IF(X249="","",IF(X249>Stats!$B$15,"Outlier","")) | Z249: =P249&" vs "&Q249 -> Chennai Super Kings vs Royal Challengers Bangalore
A250: 308 | B250: 2012 | C250: 41003 | D250: League/Playoff | E250: T01 | F250: T08 | G250: T08 | H250: field | I250: normal | J250: 0 | K250: T08 | L250: 0 | M250: 8 | N250: RE Levi | O250: V16 | P250: =INDEX(Teams!$B:$B,MATCH(E250,Teams!$A:$A,0)) -> Chennai Super Kings | Q250: =INDEX(Teams!$B:$B,MATCH(F250,Teams!$A:$A,0)) -> Mumbai Indians | R250: =INDEX(Teams!$B:$B,MATCH(G250,Teams!$A:$A,0)) -> Mumbai Indians | S250: =IF(K250="","No result",INDEX(Teams!$B:$B,MATCH(K250,Teams!$A:$A,0))) -> Mumbai Indians | T250: =INDEX(Venues!$B:$B,MATCH(O250,Venues!$A:$A,0)) -> MA Chidambaram Stadium | U250: =INDEX(Venues!$C:$C,MATCH(O250,Venues!$A:$A,0)) -> Chennai | V250: =IF(L250>0,L250&" runs",IF(M250>0,M250&" wickets","-")) -> 8 wickets | W250: =IF(G250=K250,1,0) -> 1 | X250: =IF(L250>0,L250,"") | Y250: =IF(X250="","",IF(X250>Stats!$B$15,"Outlier","")) | Z250: =P250&" vs "&Q250 -> Chennai Super Kings vs Mumbai Indians
A251: 309 | B251: 2012 | C251: 41004 | D251: League/Playoff | E251: T07 | F251: T03 | G251: T03 | H251: field | I251: normal | J251: 0 | K251: T03 | L251: 0 | M251: 8 | N251: IK Pathan | O251: V08 | P251: =INDEX(Teams!$B:$B,MATCH(E251,Teams!$A:$A,0)) -> Kolkata Knight Riders | Q251: =INDEX(Teams!$B:$B,MATCH(F251,Teams!$A:$A,0)) -> Delhi Capitals | R251: =INDEX(Teams!$B:$B,MATCH(G251,Teams!$A:$A,0)) -> Delhi Capitals | S251: =IF(K251="","No result",INDEX(Teams!$B:$B,MATCH(K251,Teams!$A:$A,0))) -> Delhi Capitals | T251: =INDEX(Venues!$B:$B,MATCH(O251,Venues!$A:$A,0)) -> Eden Gardens | U251: =INDEX(Venues!$C:$C,MATCH(O251,Venues!$A:$A,0)) -> Kolkata | V251: =IF(L251>0,L251&" runs",IF(M251>0,M251&" wickets","-")) -> 8 wickets | W251: =IF(G251=K251,1,0) -> 1 | X251: =IF(L251>0,L251,"") | Y251: =IF(X251="","",IF(X251>Stats!$B$15,"Outlier","")) | Z251: =P251&" vs "&Q251 -> Kolkata Knight Riders vs Delhi Capitals
A252: 310 | B252: 2012 | C252: 41005 | D252: League/Playoff | E252: T09 | F252: T08 | G252: T08 | H252: field | I252: normal | J252: 0 | K252: T09 | L252: 28 | M252: 0 | N252: SPD Smith | O252: V33 | P252: =INDEX(Teams!$B:$B,MATCH(E252,Teams!$A:$A,0)) -> Pune Warriors | Q252: =INDEX(Teams!$B:$B,MATCH(F252,Teams!$A:$A,0)) -> Mumbai Indians | R252: =INDEX(Teams!$B:$B,MATCH(G252,Teams!$A:$A,0)) -> Mumbai Indians | S252: =IF(K252="","No result",INDEX(Teams!$B:$B,MATCH(K252,Teams!$A:$A,0))) -> Pune Warriors | T252: =INDEX(Venues!$B:$B,MATCH(O252,Venues!$A:$A,0)) -> Wankhede Stadium | U252: =INDEX(Venues!$C:$C,MATCH(O252,Venues!$A:$A,0)) -> Mumbai | V252: =IF(L252>0,L252&" runs",IF(M252>0,M252&" wickets","-")) -> 28 runs | W252: =IF(G252=K252,1,0) -> 0 | X252: =IF(L252>0,L252,"") -> 28 | Y252: =IF(X252="","",IF(X252>Stats!$B$15,"Outlier","")) | Z252: =P252&" vs "&Q252 -> Pune Warriors vs Mumbai Indians
A253: 311 | B253: 2012 | C253: 41005 | D253: League/Playoff | E253: T10 | F253: T05 | G253: T05 | H253: field | I253: normal | J253: 0 | K253: T10 | L253: 31 | M253: 0 | N253: AM Rahane | O253: V26 | P253: =INDEX(Teams!$B:$B,MATCH(E253,Teams!$A:$A,0)) -> Rajasthan Royals | Q253: =INDEX(Teams!$B:$B,MATCH(F253,Teams!$A:$A,0)) -> Kings XI Punjab | R253: =INDEX(Teams!$B:$B,MATCH(G253,Teams!$A:$A,0)) -> Kings XI Punjab | S253: =IF(K253="","No result",INDEX(Teams!$B:$B,MATCH(K253,Teams!$A:$A,0))) -> Rajasthan Royals | T253: =INDEX(Venues!$B:$B,MATCH(O253,Venues!$A:$A,0)) -> Sawai Mansingh Stadium | U253: =INDEX(Venues!$C:$C,MATCH(O253,Venues!$A:$A,0)) -> Jaipur | V253: =IF(L253>0,L253&" runs",IF(M253>0,M253&" wickets","-")) -> 31 runs | W253: =IF(G253=K253,1,0) -> 0 | X253: =IF(L253>0,L253,"") -> 31 | Y253: =IF(X253="","",IF(X253>Stats!$B$15,"Outlier","")) | Z253: =P253&" vs "&Q253 -> Rajasthan Royals vs Kings XI Punjab
A254: 312 | B254: 2012 | C254: 41006 | D254: League/Playoff | E254: T12 | F254: T03 | G254: T03 | H254: field | I254: normal | J254: 0 | K254: T12 | L254: 20 | M254: 0 | N254: AB de Villiers | O254: V15 | P254: =INDEX(Teams!$B:$B,MATCH(E254,Teams!$A:$A,0)) -> Royal Challengers Bangalore | Q254: =INDEX(Teams!$B:$B,MATCH(F254,Teams!$A:$A,0)) -> Delhi Capitals | R254: =INDEX(Teams!$B:$B,MATCH(G254,Teams!$A:$A,0)) -> Delhi Capitals | S254: =IF(K254="","No result",INDEX(Teams!$B:$B,MATCH(K254,Teams!$A:$A,0))) -> Royal Challengers Bangalore | T254: =INDEX(Venues!$B:$B,MATCH(O254,Venues!$A:$A,0)) -> M Chinnaswamy Stadium | U254: =INDEX(Venues!$C:$C,MATCH(O254,Venues!$A:$A,0)) -> Bangalore | V254: =IF(L254>0,L254&" runs",IF(M254>0,M254&" wickets","-")) -> 20 runs | W254: =IF(G254=K254,1,0) -> 0 | X254: =IF(L254>0,L254,"") -> 20 | Y254: =IF(X254="","",IF(X254>Stats!$B$15,"Outlier","")) | Z254: =P254&" vs "&Q254 -> Royal Challengers Bangalore vs Delhi Capitals
A255: 313 | B255: 2012 | C255: 41006 | D255: League/Playoff | E255: T01 | F255: T02 | G255: T02 | H255: field | I255: normal | J255: 0 | K255: T01 | L255: 74 | M255: 0 | N255: RA Jadeja | O255: V06 | P255: =INDEX(Teams!$B:$B,MATCH(E255,Teams!$A:$A,0)) -> Chennai Super Kings | Q255: =INDEX(Teams!$B:$B,MATCH(F255,Teams!$A:$A,0)) -> Deccan Chargers | R255: =INDEX(Teams!$B:$B,MATCH(G255,Teams!$A:$A,0)) -> Deccan Chargers | S255: =IF(K255="","No result",INDEX(Teams!$B:$B,MATCH(K255,Teams!$A:$A,0))) -> Chennai Super Kings | T255: =INDEX(Venues!$B:$B,MATCH(O255,Venues!$A:$A,0)) -> Dr. Y.S. Rajasekhara Reddy ACA-VDCA Cricket Stadium | U255: =INDEX(Venues!$C:$C,MATCH(O255,Venues!$A:$A,0)) -> Visakhapatnam | V255: =IF(L255>0,L255&" runs",IF(M255>0,M255&" wickets","-")) -> 74 runs | W255: =IF(G255=K255,1,0) -> 0 | X255: =IF(L255>0,L255,"") -> 74 | Y255: =IF(X255="","",IF(X255>Stats!$B$15,"Outlier","")) | Z255: =P255&" vs "&Q255 -> Chennai Super Kings vs Deccan Chargers
... A486: 547 | B486: 2015 | C486: 42122 | D486: League/Playoff | E486: T01 | F486: T07 | G486: T07 | H486: field | I486: normal | J486: 0 | K486: T01 | L486: 2 | M486: 0 | N486: DJ Bravo | O486: V16 | P486: =INDEX(Teams!$B:$B,MATCH(E486,Teams!$A:$A,0)) -> Chennai Super Kings | Q486: =INDEX(Teams!$B:$B,MATCH(F486,Teams!$A:$A,0)) -> Kolkata Knight Riders | R486: =INDEX(Teams!$B:$B,MATCH(G486,Teams!$A:$A,0)) -> Kolkata Knight Riders | S486: =IF(K486="","No result",INDEX(Teams!$B:$B,MATCH(K486,Teams!$A:$A,0))) -> Chennai Super Kings | T486: =INDEX(Venues!$B:$B,MATCH(O486,Venues!$A:$A,0)) -> MA Chidambaram Stadium | U486: =INDEX(Venues!$C:$C,MATCH(O486,Venues!$A:$A,0)) -> Chennai | V486: =IF(L486>0,L486&" runs",IF(M486>0,M486&" wickets","-")) -> 2 runs | W486: =IF(G486=K486,1,0) -> 0 | X486: =IF(L486>0,L486,"") -> 2 | Y486: =IF(X486="","",IF(X486>Stats!$B$15,"Outlier","")) | Z486: =P486&" vs "&Q486 -> Chennai Super Kings vs Kolkata Knight Riders
A487: 546 | B487: 2015 | C487: 42123 | D487: League/Playoff | E487: T12 | F487: T10 | G487: T10 | H487: field | I487: no result | J487: 0 | L487: 0 | M487: 0 | N487: Not awarded | O487: V15 | P487: =INDEX(Teams!$B:$B,MATCH(E487,Teams!$A:$A,0)) -> Royal Challengers Bangalore | Q487: =INDEX(Teams!$B:$B,MATCH(F487,Teams!$A:$A,0)) -> Rajasthan Royals | R487: =INDEX(Teams!$B:$B,MATCH(G487,Teams!$A:$A,0)) -> Rajasthan Royals | S487: =IF(K487="","No result",INDEX(Teams!$B:$B,MATCH(K487,Teams!$A:$A,0))) -> No result | T487: =INDEX(Venues!$B:$B,MATCH(O487,Venues!$A:$A,0)) -> M Chinnaswamy Stadium | U487: =INDEX(Venues!$C:$C,MATCH(O487,Venues!$A:$A,0)) -> Bangalore | V487: =IF(L487>0,L487&" runs",IF(M487>0,M487&" wickets","-")) -> - | W487: =IF(G487=K487,1,0) -> 0 | X487: =IF(L487>0,L487,"") | Y487: =IF(X487="","",IF(X487>Stats!$B$15,"Outlier","")) | Z487: =P487&" vs "&Q487 -> Royal Challengers Bangalore vs Rajasthan Royals
A488: 527 | B488: 2015 | C488: 42124 | D488: League/Playoff | E488: T01 | F488: T07 | G488: T07 | H488: field | I488: normal | J488: 0 | K488: T07 | L488: 0 | M488: 7 | N488: AD Russell | O488: V08 | P488: =INDEX(Teams!$B:$B,MATCH(E488,Teams!$A:$A,0)) -> Chennai Super Kings | Q488: =INDEX(Teams!$B:$B,MATCH(F488,Teams!$A:$A,0)) -> Kolkata Knight Riders | R488: =INDEX(Teams!$B:$B,MATCH(G488,Teams!$A:$A,0)) -> Kolkata Knight Riders | S488: =IF(K488="","No result",INDEX(Teams!$B:$B,MATCH(K488,Teams!$A:$A,0))) -> Kolkata Knight Riders | T488: =INDEX(Venues!$B:$B,MATCH(O488,Venues!$A:$A,0)) -> Eden Gardens | U488: =INDEX(Venues!$C:$C,MATCH(O488,Venues!$A:$A,0)) -> Kolkata | V488: =IF(L488>0,L488&" runs",IF(M488>0,M488&" wickets","-")) -> 7 wickets | W488: =IF(G488=K488,1,0) -> 1 | X488: =IF(L488>0,L488,"") | Y488: =IF(X488="","",IF(X488>Stats!$B$15,"Outlier","")) | Z488: =P488&" vs "&Q488 -> Chennai Super Kings vs Kolkata Knight Riders
A489: 548 | B489: 2015 | C489: 42125 | D489: League/Playoff | E489: T05 | F489: T03 | G489: T03 | H489: field | I489: normal | J489: 0 | K489: T03 | L489: 0 | M489: 9 | N489: NM Coulter-Nile | O489: V09 | P489: =INDEX(Teams!$B:$B,MATCH(E489,Teams!$A:$A,0)) -> Kings XI Punjab | Q489: =INDEX(Teams!$B:$B,MATCH(F489,Teams!$A:$A,0)) -> Delhi Capitals | R489: =INDEX(Teams!$B:$B,MATCH(G489,Teams!$A:$A,0)) -> Delhi Capitals | S489: =IF(K489="","No result",INDEX(Teams!$B:$B,MATCH(K489,Teams!$A:$A,0))) -> Delhi Capitals | T489: =INDEX(Venues!$B:$B,MATCH(O489,Venues!$A:$A,0)) -> Feroz Shah Kotla | U489: =INDEX(Venues!$C:$C,MATCH(O489,Venues!$A:$A,0)) -> Delhi | V489: =IF(L489>0,L489&" runs",IF(M489>0,M489&" wickets","-")) -> 9 wickets | W489: =IF(G489=K489,1,0) -> 1 | X489: =IF(L489>0,L489,"") | Y489: =IF(X489="","",IF(X489>Stats!$B$15,"Outlier","")) | Z489: =P489&" vs "&Q489 -> Kings XI Punjab vs Delhi Capitals
A490: 549 | B490: 2015 | C490: 42125 | D490: League/Playoff | E490: T08 | F490: T10 | G490: T10 | H490: field | I490: normal | J490: 0 | K490: T08 | L490: 8 | M490: 0 | N490: AT Rayudu | O490: V33 | P490: =INDEX(Teams!$B:$B,MATCH(E490,Teams!$A:$A,0)) -> Mumbai Indians | Q490: =INDEX(Teams!$B:$B,MATCH(F490,Teams!$A:$A,0)) -> Rajasthan Royals | R490: =INDEX(Teams!$B:$B,MATCH(G490,Teams!$A:$A,0)) -> Rajasthan Royals | S490: =IF(K490="","No result",INDEX(Teams!$B:$B,MATCH(K490,Teams!$A:$A,0))) -> Mumbai Indians | T490: =INDEX(Venues!$B:$B,MATCH(O490,Venues!$A:$A,0)) -> Wankhede Stadium | U490: =INDEX(Venues!$C:$C,MATCH(O490,Venues!$A:$A,0)) -> Mumbai | V490: =IF(L490>0,L490&" runs",IF(M490>0,M490&" wickets","-")) -> 8 runs | W490: =IF(G490=K490,1,0) -> 0 | X490: =IF(L490>0,L490,"") -> 8 | Y490: =IF(X490="","",IF(X490>Stats!$B$15,"Outlier","")) | Z490: =P490&" vs "&Q490 -> Mumbai Indians vs Rajasthan Royals
A491: 550 | B491: 2015 | C491: 42126 | D491: League/Playoff | E491: T07 | F491: T12 | G491: T12 | H491: field | I491: normal | J491: 0 | K491: T12 | L491: 0 | M491: 7 | N491: Mandeep Singh | O491: V15 | P491: =INDEX(Teams!$B:$B,MATCH(E491,Teams!$A:$A,0)) -> Kolkata Knight Riders | Q491: =INDEX(Teams!$B:$B,MATCH(F491,Teams!$A:$A,0)) -> Royal Challengers Bangalore | R491: =INDEX(Teams!$B:$B,MATCH(G491,Teams!$A:$A,0)) -> Royal Challengers Bangalore | S491: =IF(K491="","No result",INDEX(Teams!$B:$B,MATCH(K491,Teams!$A:$A,0))) -> Royal Challengers Bangalore | T491: =INDEX(Venues!$B:$B,MATCH(O491,Venues!$A:$A,0)) -> M Chinnaswamy Stadium | U491: =INDEX(Venues!$C:$C,MATCH(O491,Venues!$A:$A,0)) -> Bangalore | V491: =IF(L491>0,L491&" runs",IF(M491>0,M491&" wickets","-")) -> 7 wickets | W491: =IF(G491=K491,1,0) -> 1 | X491: =IF(L491>0,L491,"") | Y491: =IF(X491="","",IF(X491>Stats!$B$15,"Outlier","")) | Z491: =P491&" vs "&Q491 -> Kolkata Knight Riders vs Royal Challengers Bangalore
A492: 551 | B492: 2015 | C492: 42126 | D492: League/Playoff | E492: T13 | F492: T01 | G492: T01 | H492: field | I492: normal | J492: 0 | K492: T13 | L492: 22 | M492: 0 | N492: DA Warner | O492: V23 | P492: =INDEX(Teams!$B:$B,MATCH(E492,Teams!$A:$A,0)) -> Sunrisers Hyderabad | Q492: =INDEX(Teams!$B:$B,MATCH(F492,Teams!$A:$A,0)) -> Chennai Super Kings | R492: =INDEX(Teams!$B:$B,MATCH(G492,Teams!$A:$A,0)) -> Chennai Super Kings | S492: =IF(K492="","No result",INDEX(Teams!$B:$B,MATCH(K492,Teams!$A:$A,0))) -> Sunrisers Hyderabad | T492: =INDEX(Venues!$B:$B,MATCH(O492,Venues!$A:$A,0)) -> Rajiv Gandhi International Stadium | U492: =INDEX(Venues!$C:$C,MATCH(O492,Venues!$A:$A,0)) -> Hyderabad | V492: =IF(L492>0,L492&" runs",IF(M492>0,M492&" wickets","-")) -> 22 runs | W492: =IF(G492=K492,1,0) -> 0 | X492: =IF(L492>0,L492,"") -> 22 | Y492: =IF(X492="","",IF(X492>Stats!$B$15,"Outlier","")) | Z492: =P492&" vs "&Q492 -> Sunrisers Hyderabad vs Chennai Super Kings
A493: 552 | B493: 2015 | C493: 42127 | D493: League/Playoff | E493: T08 | F493: T05 | G493: T08 | H493: bat | I493: normal | J493: 0 | K493: T08 | L493: 23 | M493: 0 | N493: LMP Simmons | O493: V22 | P493: =INDEX(Teams!$B:$B,MATCH(E493,Teams!$A:$A,0)) -> Mumbai Indians | Q493: =INDEX(Teams!$B:$B,MATCH(F493,Teams!$A:$A,0)) -> Kings XI Punjab | R493: =INDEX(Teams!$B:$B,MATCH(G493,Teams!$A:$A,0)) -> Mumbai Indians | S493: =IF(K493="","No result",INDEX(Teams!$B:$B,MATCH(K493,Teams!$A:$A,0))) -> Mumbai Indians | T493: =INDEX(Venues!$B:$B,MATCH(O493,Venues!$A:$A,0)) -> Punjab Cricket Association IS Bindra Stadium | U493: =INDEX(Venues!$C:$C,MATCH(O493,Venues!$A:$A,0)) -> Chandigarh | V493: =IF(L493>0,L493&" runs",IF(M493>0,M493&" wickets","-")) -> 23 runs | W493: =IF(G493=K493,1,0) -> 1 | X493: =IF(L493>0,L493,"") -> 23 | Y493: =IF(X493="","",IF(X493>Stats!$B$15,"Outlier","")) | Z493: =P493&" vs "&Q493 -> Mumbai Indians vs Kings XI Punjab
A494: 553 | B494: 2015 | C494: 42127 | D494: League/Playoff | E494: T10 | F494: T03 | G494: T03 | H494: field | I494: normal | J494: 0 | K494: T10 | L494: 14 | M494: 0 | N494: AM Rahane | O494: V02 | P494: =INDEX(Teams!$B:$B,MATCH(E494,Teams!$A:$A,0)) -> Rajasthan Royals | Q494: =INDEX(Teams!$B:$B,MATCH(F494,Teams!$A:$A,0)) -> Delhi Capitals | R494: =INDEX(Teams!$B:$B,MATCH(G494,Teams!$A:$A,0)) -> Delhi Capitals | S494: =IF(K494="","No result",INDEX(Teams!$B:$B,MATCH(K494,Teams!$A:$A,0))) -> Rajasthan Royals | T494: =INDEX(Venues!$B:$B,MATCH(O494,Venues!$A:$A,0)) -> Brabourne Stadium | U494: =INDEX(Venues!$C:$C,MATCH(O494,Venues!$A:$A,0)) -> Mumbai | V494: =IF(L494>0,L494&" runs",IF(M494>0,M494&" wickets","-")) -> 14 runs | W494: =IF(G494=K494,1,0) -> 0 | X494: =IF(L494>0,L494,"") -> 14 | Y494: =IF(X494="","",IF(X494>Stats!$B$15,"Outlier","")) | Z494: =P494&" vs "&Q494 -> Rajasthan Royals vs Delhi Capitals
A495: 554 | B495: 2015 | C495: 42128 | D495: League/Playoff | E495: T01 | F495: T12 | G495: T01 | H495: bat | I495: normal | J495: 0 | K495: T01 | L495: 24 | M495: 0 | N495: SK Raina | O495: V16 | P495: =INDEX(Teams!$B:$B,MATCH(E495,Teams!$A:$A,0)) -> Chennai Super Kings | Q495: =INDEX(Teams!$B:$B,MATCH(F495,Teams!$A:$A,0)) -> Royal Challengers Bangalore | R495: =INDEX(Teams!$B:$B,MATCH(G495,Teams!$A:$A,0)) -> Chennai Super Kings | S495: =IF(K495="","No result",INDEX(Teams!$B:$B,MATCH(K495,Teams!$A:$A,0))) -> Chennai Super Kings | T495: =INDEX(Venues!$B:$B,MATCH(O495,Venues!$A:$A,0)) -> MA Chidambaram Stadium | U495: =INDEX(Venues!$C:$C,MATCH(O495,Venues!$A:$A,0)) -> Chennai | V495: =IF(L495>0,L495&" runs",IF(M495>0,M495&" wickets","-")) -> 24 runs | W495: =IF(G495=K495,1,0) -> 1 | X495: =IF(L495>0,L495,"") -> 24 | Y495: =IF(X495="","",IF(X495>Stats!$B$15,"Outlier","")) | Z495: =P495&" vs "&Q495 -> Chennai Super Kings vs Royal Challengers Bangalore
A496: 555 | B496: 2015 | C496: 42128 | D496: League/Playoff | E496: T07 | F496: T13 | G496: T13 | H496: field | I496: normal | J496: 0 | K496: T07 | L496: 35 | M496: 0 | N496: UT Yadav | O496: V08 | P496: =INDEX(Teams!$B:$B,MATCH(E496,Teams!$A:$A,0)) -> Kolkata Knight Riders | Q496: =INDEX(Teams!$B:$B,MATCH(F496,Teams!$A:$A,0)) -> Sunrisers Hyderabad | R496: =INDEX(Teams!$B:$B,MATCH(G496,Teams!$A:$A,0)) -> Sunrisers Hyderabad | S496: =IF(K496="","No result",INDEX(Teams!$B:$B,MATCH(K496,Teams!$A:$A,0))) -> Kolkata Knight Riders | T496: =INDEX(Venues!$B:$B,MATCH(O496,Venues!$A:$A,0)) -> Eden Gardens | U496: =INDEX(Venues!$C:$C,MATCH(O496,Venues!$A:$A,0)) -> Kolkata | V496: =IF(L496>0,L496&" runs",IF(M496>0,M496&" wickets","-")) -> 35 runs | W496: =IF(G496=K496,1,0) -> 0 | X496: =IF(L496>0,L496,"") -> 35 | Y496: =IF(X496="","",IF(X496>Stats!$B$15,"Outlier","")) | Z496: =P496&" vs "&Q496 -> Kolkata Knight Riders vs Sunrisers Hyderabad
A497: 556 | B497: 2015 | C497: 42129 | D497: League/Playoff | E497: T03 | F497: T08 | G497: T03 | H497: bat | I497: normal | J497: 0 | K497: T08 | L497: 0 | M497: 5 | N497: Harbhajan Singh | O497: V33 | P497: =INDEX(Teams!$B:$B,MATCH(E497,Teams!$A:$A,0)) -> Delhi Capitals | Q497: =INDEX(Teams!$B:$B,MATCH(F497,Teams!$A:$A,0)) -> Mumbai Indians | R497: =INDEX(Teams!$B:$B,MATCH(G497,Teams!$A:$A,0)) -> Delhi Capitals | S497: =IF(K497="","No result",INDEX(Teams!$B:$B,MATCH(K497,Teams!$A:$A,0))) -> Mumbai Indians | T497: =INDEX(Venues!$B:$B,MATCH(O497,Venues!$A:$A,0)) -> Wankhede Stadium | U497: =INDEX(Venues!$C:$C,MATCH(O497,Venues!$A:$A,0)) -> Mumbai | V497: =IF(L497>0,L497&" runs",IF(M497>0,M497&" wickets","-")) -> 5 wickets | W497: =IF(G497=K497,1,0) -> 0 | X497: =IF(L497>0,L497,"") | Y497: =IF(X497="","",IF(X497>Stats!$B$15,"Outlier","")) | Z497: =P497&" vs "&Q497 -> Delhi Capitals vs Mumbai Indians
A498: 557 | B498: 2015 | C498: 42130 | D498: League/Playoff | E498: T12 | F498: T05 | G498: T05 | H498: field | I498: normal | J498: 0 | K498: T12 | L498: 138 | M498: 0 | N498: CH Gayle | O498: V15 | P498: =INDEX(Teams!$B:$B,MATCH(E498,Teams!$A:$A,0)) -> Royal Challengers Bangalore | Q498: =INDEX(Teams!$B:$B,MATCH(F498,Teams!$A:$A,0)) -> Kings XI Punjab | R498: =INDEX(Teams!$B:$B,MATCH(G498,Teams!$A:$A,0)) -> Kings XI Punjab | S498: =IF(K498="","No result",INDEX(Teams!$B:$B,MATCH(K498,Teams!$A:$A,0))) -> Royal Challengers Bangalore | T498: =INDEX(Venues!$B:$B,MATCH(O498,Venues!$A:$A,0)) -> M Chinnaswamy Stadium | U498: =INDEX(Venues!$C:$C,MATCH(O498,Venues!$A:$A,0)) -> Bangalore | V498: =IF(L498>0,L498&" runs",IF(M498>0,M498&" wickets","-")) -> 138 runs | W498: =IF(G498=K498,1,0) -> 0 | X498: =IF(L498>0,L498,"") -> 138 | Y498: =IF(X498="","",IF(X498>Stats!$B$15,"Outlier","")) -> Outlier | Z498: =P498&" vs "&Q498 -> Royal Challengers Bangalore vs Kings XI Punjab
...

Sheet Summary
A1: IPL 2008-2019 summary (formulas on the Matches sheet)
A3: Matches | B3: =COUNTA(Matches!$A$2:$A$757) -> 756 | H3: Season | I3: Matches | J3: Field % | K3: Won batting first | L3: Won chasing | M3: Chase win %
A4: Matches with a result | B4: =COUNTA(Matches!$K$2:$K$757) -> 752 | H4: 2008 | I4: =COUNTIFS(Matches!$B$2:$B$757,H4) -> 58 | J4: =COUNTIFS(Matches!$B$2:$B$757,H4,Matches!$H$2:$H$757,"field")/I4 -> 0.55172414 | K4: =COUNTIFS(Matches!$B$2:$B$757,H4,Matches!$L$2:$L$757,">0") -> 24 | L4: =COUNTIFS(Matches!$B$2:$B$757,H4,Matches!$M$2:$M$757,">0") -> 34 | M4: =L4/(K4+L4) -> 0.5862069
A5: Toss winner also won the match | B5: =SUM(Matches!$W$2:$W$757)/B4 -> 0.52260638 | H5: 2009 | I5: =COUNTIFS(Matches!$B$2:$B$757,H5) -> 57 | J5: =COUNTIFS(Matches!$B$2:$B$757,H5,Matches!$H$2:$H$757,"field")/I5 -> 0.38596491 | K5: =COUNTIFS(Matches!$B$2:$B$757,H5,Matches!$L$2:$L$757,">0") -> 27 | L5: =COUNTIFS(Matches!$B$2:$B$757,H5,Matches!$M$2:$M$757,">0") -> 29 | M5: =L5/(K5+L5) -> 0.51785714
A6: Chose to field after winning toss | B6: =COUNTIFS(Matches!$H$2:$H$757,"field")/B3 -> 0.61243386 | H6: 2010 | I6: =COUNTIFS(Matches!$B$2:$B$757,H6) -> 60 | J6: =COUNTIFS(Matches!$B$2:$B$757,H6,Matches!$H$2:$H$757,"field")/I6 -> 0.35 | K6: =COUNTIFS(Matches!$B$2:$B$757,H6,Matches!$L$2:$L$757,">0") -> 31 | L6: =COUNTIFS(Matches!$B$2:$B$757,H6,Matches!$M$2:$M$757,">0") -> 28 | M6: =L6/(K6+L6) -> 0.47457627
A7: Matches using Duckworth-Lewis | B7: =SUM(Matches!$J$2:$J$757) -> 19 | H7: 2011 | I7: =COUNTIFS(Matches!$B$2:$B$757,H7) -> 73 | J7: =COUNTIFS(Matches!$B$2:$B$757,H7,Matches!$H$2:$H$757,"field")/I7 -> 0.65753425 | K7: =COUNTIFS(Matches!$B$2:$B$757,H7,Matches!$L$2:$L$757,">0") -> 33 | L7: =COUNTIFS(Matches!$B$2:$B$757,H7,Matches!$M$2:$M$757,">0") -> 39 | M7: =L7/(K7+L7) -> 0.54166667
H8: 2012 | I8: =COUNTIFS(Matches!$B$2:$B$757,H8) -> 74 | J8: =COUNTIFS(Matches!$B$2:$B$757,H8,Matches!$H$2:$H$757,"field")/I8 -> 0.5 | K8: =COUNTIFS(Matches!$B$2:$B$757,H8,Matches!$L$2:$L$757,">0") -> 34 | L8: =COUNTIFS(Matches!$B$2:$B$757,H8,Matches!$M$2:$M$757,">0") -> 40 | M8: =L8/(K8+L8) -> 0.54054054
H9: 2013 | I9: =COUNTIFS(Matches!$B$2:$B$757,H9) -> 76 | J9: =COUNTIFS(Matches!$B$2:$B$757,H9,Matches!$H$2:$H$757,"field")/I9 -> 0.40789474 | K9: =COUNTIFS(Matches!$B$2:$B$757,H9,Matches!$L$2:$L$757,">0") -> 37 | L9: =COUNTIFS(Matches!$B$2:$B$757,H9,Matches!$M$2:$M$757,">0") -> 37 | M9: =L9/(K9+L9) -> 0.5
A10: Franchise | B10: Played | C10: Wins | D10: Win % | E10: Titles | H10: 2014 | I10: =COUNTIFS(Matches!$B$2:$B$757,H10) -> 60 | J10: =COUNTIFS(Matches!$B$2:$B$757,H10,Matches!$H$2:$H$757,"field")/I10 -> 0.68333333 | K10: =COUNTIFS(Matches!$B$2:$B$757,H10,Matches!$L$2:$L$757,">0") -> 22 | L10: =COUNTIFS(Matches!$B$2:$B$757,H10,Matches!$M$2:$M$757,">0") -> 37 | M10: =L10/(K10+L10) -> 0.62711864
A11: Mumbai Indians | B11: =COUNTIFS(Matches!$P$2:$P$757,A11,Matches!$S$2:$S$757,"<>No result")+COUNTIFS(Matches!$Q$2:$Q$757,A11,Matches!$S$2:$S$757,"<>No result") -> 187 | C11: =COUNTIFS(Matches!$S$2:$S$757,A11) -> 109 | D11: =C11/B11 -> 0.5828877 | E11: =COUNTIFS(Matches!$S$2:$S$757,A11,Matches!$D$2:$D$757,"Final") -> 4 | H11: 2015 | I11: =COUNTIFS(Matches!$B$2:$B$757,H11) -> 59 | J11: =COUNTIFS(Matches!$B$2:$B$757,H11,Matches!$H$2:$H$757,"field")/I11 -> 0.57627119 | K11: =COUNTIFS(Matches!$B$2:$B$757,H11,Matches!$L$2:$L$757,">0") -> 32 | L11: =COUNTIFS(Matches!$B$2:$B$757,H11,Matches!$M$2:$M$757,">0") -> 24 | M11: =L11/(K11+L11) -> 0.42857143
A12: Chennai Super Kings | B12: =COUNTIFS(Matches!$P$2:$P$757,A12,Matches!$S$2:$S$757,"<>No result")+COUNTIFS(Matches!$Q$2:$Q$757,A12,Matches!$S$2:$S$757,"<>No result") -> 164 | C12: =COUNTIFS(Matches!$S$2:$S$757,A12) -> 100 | D12: =C12/B12 -> 0.6097561 | E12: =COUNTIFS(Matches!$S$2:$S$757,A12,Matches!$D$2:$D$757,"Final") -> 3 | H12: 2016 | I12: =COUNTIFS(Matches!$B$2:$B$757,H12) -> 60 | J12: =COUNTIFS(Matches!$B$2:$B$757,H12,Matches!$H$2:$H$757,"field")/I12 -> 0.81666667 | K12: =COUNTIFS(Matches!$B$2:$B$757,H12,Matches!$L$2:$L$757,">0") -> 21 | L12: =COUNTIFS(Matches!$B$2:$B$757,H12,Matches!$M$2:$M$757,">0") -> 39 | M12: =L12/(K12+L12) -> 0.65
A13: Kolkata Knight Riders | B13: =COUNTIFS(Matches!$P$2:$P$757,A13,Matches!$S$2:$S$757,"<>No result")+COUNTIFS(Matches!$Q$2:$Q$757,A13,Matches!$S$2:$S$757,"<>No result") -> 178 | C13: =COUNTIFS(Matches!$S$2:$S$757,A13) -> 92 | D13: =C13/B13 -> 0.51685393 | E13: =COUNTIFS(Matches!$S$2:$S$757,A13,Matches!$D$2:$D$757,"Final") -> 2 | H13: 2017 | I13: =COUNTIFS(Matches!$B$2:$B$757,H13) -> 59 | J13: =COUNTIFS(Matches!$B$2:$B$757,H13,Matches!$H$2:$H$757,"field")/I13 -> 0.81355932 | K13: =COUNTIFS(Matches!$B$2:$B$757,H13,Matches!$L$2:$L$757,">0") -> 26 | L13: =COUNTIFS(Matches!$B$2:$B$757,H13,Matches!$M$2:$M$757,">0") -> 32 | M13: =L13/(K13+L13) -> 0.55172414
A14: Royal Challengers Bangalore | B14: =COUNTIFS(Matches!$P$2:$P$757,A14,Matches!$S$2:$S$757,"<>No result")+COUNTIFS(Matches!$Q$2:$Q$757,A14,Matches!$S$2:$S$757,"<>No result") -> 177 | C14: =COUNTIFS(Matches!$S$2:$S$757,A14) -> 84 | D14: =C14/B14 -> 0.47457627 | E14: =COUNTIFS(Matches!$S$2:$S$757,A14,Matches!$D$2:$D$757,"Final") -> 0 | H14: 2018 | I14: =COUNTIFS(Matches!$B$2:$B$757,H14) -> 60 | J14: =COUNTIFS(Matches!$B$2:$B$757,H14,Matches!$H$2:$H$757,"field")/I14 -> 0.83333333 | K14: =COUNTIFS(Matches!$B$2:$B$757,H14,Matches!$L$2:$L$757,">0") -> 28 | L14: =COUNTIFS(Matches!$B$2:$B$757,H14,Matches!$M$2:$M$757,">0") -> 32 | M14: =L14/(K14+L14) -> 0.53333333
A15: Kings XI Punjab | B15: =COUNTIFS(Matches!$P$2:$P$757,A15,Matches!$S$2:$S$757,"<>No result")+COUNTIFS(Matches!$Q$2:$Q$757,A15,Matches!$S$2:$S$757,"<>No result") -> 176 | C15: =COUNTIFS(Matches!$S$2:$S$757,A15) -> 82 | D15: =C15/B15 -> 0.46590909 | E15: =COUNTIFS(Matches!$S$2:$S$757,A15,Matches!$D$2:$D$757,"Final") -> 0 | H15: 2019 | I15: =COUNTIFS(Matches!$B$2:$B$757,H15) -> 60 | J15: =COUNTIFS(Matches!$B$2:$B$757,H15,Matches!$H$2:$H$757,"field")/I15 -> 0.83333333 | K15: =COUNTIFS(Matches!$B$2:$B$757,H15,Matches!$L$2:$L$757,">0") -> 22 | L15: =COUNTIFS(Matches!$B$2:$B$757,H15,Matches!$M$2:$M$757,">0") -> 35 | M15: =L15/(K15+L15) -> 0.61403509
A16: Delhi Capitals | B16: =COUNTIFS(Matches!$P$2:$P$757,A16,Matches!$S$2:$S$757,"<>No result")+COUNTIFS(Matches!$Q$2:$Q$757,A16,Matches!$S$2:$S$757,"<>No result") -> 175 | C16: =COUNTIFS(Matches!$S$2:$S$757,A16) -> 77 | D16: =C16/B16 -> 0.44 | E16: =COUNTIFS(Matches!$S$2:$S$757,A16,Matches!$D$2:$D$757,"Final") -> 0
A17: Rajasthan Royals | B17: =COUNTIFS(Matches!$P$2:$P$757,A17,Matches!$S$2:$S$757,"<>No result")+COUNTIFS(Matches!$Q$2:$Q$757,A17,Matches!$S$2:$S$757,"<>No result") -> 145 | C17: =COUNTIFS(Matches!$S$2:$S$757,A17) -> 75 | D17: =C17/B17 -> 0.51724138 | E17: =COUNTIFS(Matches!$S$2:$S$757,A17,Matches!$D$2:$D$757,"Final") -> 1
A18: Sunrisers Hyderabad | B18: =COUNTIFS(Matches!$P$2:$P$757,A18,Matches!$S$2:$S$757,"<>No result")+COUNTIFS(Matches!$Q$2:$Q$757,A18,Matches!$S$2:$S$757,"<>No result") -> 108 | C18: =COUNTIFS(Matches!$S$2:$S$757,A18) -> 58 | D18: =C18/B18 -> 0.53703704 | E18: =COUNTIFS(Matches!$S$2:$S$757,A18,Matches!$D$2:$D$757,"Final") -> 1
A19: Deccan Chargers | B19: =COUNTIFS(Matches!$P$2:$P$757,A19,Matches!$S$2:$S$757,"<>No result")+COUNTIFS(Matches!$Q$2:$Q$757,A19,Matches!$S$2:$S$757,"<>No result") -> 75 | C19: =COUNTIFS(Matches!$S$2:$S$757,A19) -> 29 | D19: =C19/B19 -> 0.38666667 | E19: =COUNTIFS(Matches!$S$2:$S$757,A19,Matches!$D$2:$D$757,"Final") -> 1
A20: Rising Pune Supergiant | B20: =COUNTIFS(Matches!$P$2:$P$757,A20,Matches!$S$2:$S$757,"<>No result")+COUNTIFS(Matches!$Q$2:$Q$757,A20,Matches!$S$2:$S$757,"<>No result") -> 30 | C20: =COUNTIFS(Matches!$S$2:$S$757,A20) -> 15 | D20: =C20/B20 -> 0.5 | E20: =COUNTIFS(Matches!$S$2:$S$757,A20,Matches!$D$2:$D$757,"Final") -> 0
A21: Gujarat Lions | B21: =COUNTIFS(Matches!$P$2:$P$757,A21,Matches!$S$2:$S$757,"<>No result")+COUNTIFS(Matches!$Q$2:$Q$757,A21,Matches!$S$2:$S$757,"<>No result") -> 30 | C21: =COUNTIFS(Matches!$S$2:$S$757,A21) -> 13 | D21: =C21/B21 -> 0.43333333 | E21: =COUNTIFS(Matches!$S$2:$S$757,A21,Matches!$D$2:$D$757,"Final") -> 0
A22: Pune Warriors | B22: =COUNTIFS(Matches!$P$2:$P$757,A22,Matches!$S$2:$S$757,"<>No result")+COUNTIFS(Matches!$Q$2:$Q$757,A22,Matches!$S$2:$S$757,"<>No result") -> 45 | C22: =COUNTIFS(Matches!$S$2:$S$757,A22) -> 12 | D22: =C22/B22 -> 0.26666667 | E22: =COUNTIFS(Matches!$S$2:$S$757,A22,Matches!$D$2:$D$757,"Final") -> 0
A23: Kochi Tuskers Kerala | B23: =COUNTIFS(Matches!$P$2:$P$757,A23,Matches!$S$2:$S$757,"<>No result")+COUNTIFS(Matches!$Q$2:$Q$757,A23,Matches!$S$2:$S$757,"<>No result") -> 14 | C23: =COUNTIFS(Matches!$S$2:$S$757,A23) -> 6 | D23: =C23/B23 -> 0.42857143 | E23: =COUNTIFS(Matches!$S$2:$S$757,A23,Matches!$D$2:$D$757,"Final") -> 0

Sheet Stats
A1: Distribution and outliers: runs margin (matches won by runs)
A3: Measure | B3: Value | D3: Margin (runs) | E3: Matches
A4: Count | B4: =COUNT(Matches!$X$2:$X$757) -> 337 | D4: 1-10 | E4: =COUNTIFS(Matches!$X$2:$X$757,">0",Matches!$X$2:$X$757,"<=10") -> 80
A5: Mean | B5: =AVERAGE(Matches!$X$2:$X$757) -> 29.79822 | D5: 11-20 | E5: =COUNTIFS(Matches!$X$2:$X$757,">10",Matches!$X$2:$X$757,"<=20") -> 80
A6: Median | B6: =MEDIAN(Matches!$X$2:$X$757) -> 22 | D6: 21-30 | E6: =COUNTIFS(Matches!$X$2:$X$757,">20",Matches!$X$2:$X$757,"<=30") -> 56
A7: Mode | B7: =MODE(Matches!$X$2:$X$757) -> 14 | D7: 31-40 | E7: =COUNTIFS(Matches!$X$2:$X$757,">30",Matches!$X$2:$X$757,"<=40") -> 43
A8: Standard deviation | B8: =STDEV(Matches!$X$2:$X$757) -> 27.281616 | D8: 41-60 | E8: =COUNTIFS(Matches!$X$2:$X$757,">40",Matches!$X$2:$X$757,"<=60") -> 35
A9: Minimum | B9: =MIN(Matches!$X$2:$X$757) -> 1 | D9: 61-80 | E9: =COUNTIFS(Matches!$X$2:$X$757,">60",Matches!$X$2:$X$757,"<=80") -> 20
A10: Maximum | B10: =MAX(Matches!$X$2:$X$757) -> 146 | D10: 81+ | E10: =COUNTIFS(Matches!$X$2:$X$757,">80",Matches!$X$2:$X$757,"<=1000000") -> 23
A11: Q1 (25th percentile) | B11: =QUARTILE(Matches!$X$2:$X$757,1) -> 11
A12: Q3 (75th percentile) | B12: =QUARTILE(Matches!$X$2:$X$757,3) -> 39
A13: IQR (Q3 - Q1) | B13: =B12-B11 -> 28
A14: Lower fence (Q1 - 1.5 x IQR) | B14: =B11-1.5*B13 -> -31
A15: Upper fence (Q3 + 1.5 x IQR) | B15: =B12+1.5*B13 -> 81
A16: Matches above the upper fence | B16: =COUNTIF(Matches!$X$2:$X$757,">"&B15) -> 23
A17: Skewness | B17: =SKEW(Matches!$X$2:$X$757) -> 1.7570395
A20: How to read this
A21: Mean is above the median and skewness is positive: a few huge wins pull the average up (right-skewed).
A22: Most run wins are modest, so the median is the better 'typical margin'.
A23: Matches above the upper fence are flagged on the Matches sheet. They are real, record-size wins, so they are kept.
A24: Margins by wickets are a different measure (0-10) and are analysed separately.
